File: Example Files/Instruments/Rigaku_SmartLab/XRD/C4_02052_5to50_005005.ras
*RAS_DATA_START
*RAS_HEADER_START
*DISP_FMT_X "%.1f"
*DISP_FMT_Y "%.0f"
*DISP_FULLSCALE "4054.6888342422"
*DISP_LINE_COLOR "255.0000000000"
*DISP_LINE_STYLE "0.0000000000"
*DISP_LINE_WIDTH "0.2500000000"
*DISP_NOTE "Collected Data-50"
*DISP_OFFSET_Y "0.0000000000"
*DISP_PEAKSEARCH_UNIT_Y "cps"
*DISP_RANGE_BOTTOM "0.0100000000"
*DISP_RANGE_LEFT "5.0000000000"
*DISP_RANGE_LOGCUTOFF "0.0100000000"
*DISP_RANGE_RIGHT "50.0000000000"
*DISP_RANGE_TOP "4054.6888342422"
*DISP_SCALE_MODE_Y "2.0000000000"
*DISP_TAB_NAME "2-Theta/Omega"
*DISP_TITLE_Y "Intensity"
*DISP_UNIT_Y "cps"
*DISP_WINDOW_NAME "MSG_MACROENGINE"
*FILE_COMMENT " "
*FILE_MD5 ""
*FILE_MEMO " "
*FILE_OPERATOR "Administrator"
*FILE_PART_ID "MEAS_KHP2_00061"
*FILE_SAMPLE " "
*FILE_TYPE "RAS_RAW"
*FILE_USERGROUP "System Manager"
*FILE_VERSION "1.0000000000"
*HW_ATTACHMENT_ID "ATT0023"
*HW_ATTACHMENT_NAME "XY-4inch|XY-4inch"
*HW_COUNTER_ID-0 "CUT0021"
*HW_COUNTER_ID-1 "CUT0051"
*HW_COUNTER_ID-2 "CUT0020"
*HW_COUNTER_ID-3 "CSL0021"
*HW_COUNTER_ID-4 "CMC0021"
*HW_COUNTER_NAME-0 "SC-70|SC-70"
*HW_COUNTER_NAME-1 "HyPix 3000(H)|HyPix 3000(H)"
*HW_COUNTER_NAME-2 "None|None"
*HW_COUNTER_NAME-3 "BBM|BBM"
*HW_COUNTER_NAME-4 "検出器モノクロメータ|Detector monochromator"
*HW_COUNTER_SELECT_NAME "HyPix 3000(H)|HyPix 3000(H)"
*HW_GONIOMETER_ID "GON0023"
*HW_GONIOMETER_NAME "SmartLab|SmartLab"
*HW_GONIOMETER_RADIUS-0 "90.0"
*HW_GONIOMETER_RADIUS-1 "114.0"
*HW_GONIOMETER_RADIUS-2 "190.0"
*HW_GONIOMETER_RADIUS-3 "300.0"
*HW_GONIOMETER_RADIUS-4 "187.0"
*HW_GONIOMETER_RADIUS-5 "300.0"
*HW_GONIOMETER_RADIUS-6 "113.0"
*HW_GONIOMETER_RADIUS-7 "331.0"
*HW_I_OPT_ID-0 "CBO0021"
*HW_I_OPT_ID-1 "ICR0023"
*HW_I_OPT_ID-2 "ISL0021"
*HW_I_OPT_ID-3 "ISO0021"
*HW_I_OPT_ID-4 "IAD0021"
*HW_I_OPT_ID-5 "IPR0001"
*HW_I_OPT_NAME-0 "CBOユニット|CBO unit"
*HW_I_OPT_NAME-1 "標準入射光学ユニット|Standard incident optical unit"
*HW_I_OPT_NAME-2 "標準入射スリットボックス|Standard incident slit box"
*HW_I_OPT_NAME-3 "入射平行スリット|Incident parallel slit"
*HW_I_OPT_NAME-4 "長手制限スリット|Length limiting slit"
*HW_I_OPT_NAME-5 "None|None"
*HW_R_ATTENUATER_AUTOMODE "0"
*HW_R_OPT_ID-0 "RSS0022"
*HW_R_OPT_ID-1 "RCR0022"
*HW_R_OPT_ID-2 "RSO0021"
*HW_R_OPT_ID-3 "RRS0022"
*HW_R_OPT_ID-4 "ATN0020"
*HW_R_OPT_ID-5 "RFL0021"
*HW_R_OPT_ID-6 "RAD0021"
*HW_R_OPT_NAME-0 "受光スリットボックス1(Zr軸付)|Receiving slit box # 1 (w/ Zr Axis)"
*HW_R_OPT_NAME-1 "標準受光光学ユニット1|Standard receiving unit # 1"
*HW_R_OPT_NAME-2 "標準受光光学ユニット2|Standard receiving optical unit # 2"
*HW_R_OPT_NAME-3 "標準受光スリットボックス2|Standard receiving slit box # 2"
*HW_R_OPT_NAME-4 "無し|None"
*HW_R_OPT_NAME-5 "Cu Kβ|Cu K-beta"
*HW_R_OPT_NAME-6 "調整用受光スリット|Alignment receiving slit"
*HW_SAMPLE_HOLDER_ID "SMP0021"
*HW_SAMPLE_HOLDER_NAME "χφZクレードル|Chi phi Z cradle"
*HW_XG_CURRENT_MAX "50"
*HW_XG_CURRENT_MIN "2"
*HW_XG_CURRENT_RESOLUTION "2"
*HW_XG_CURRENT_UNIT "mA"
*HW_XG_FOCUS "1mm x 10mm"
*HW_XG_FOCUS_TYPE "Normal"
*HW_XG_ID ""
*HW_XG_NAME "3kW 封入管(ID:1200)|3kW Sealed tube(ID:1200)"
*HW_XG_TARGET_ATOMIC_NUMBER "29.0000000000"
*HW_XG_TARGET_NAME "Cu"
*HW_XG_TYPE "Hermetic"
*HW_XG_VOLTAGE_MAX "60"
*HW_XG_VOLTAGE_MIN "20"
*HW_XG_VOLTAGE_RESOLUTION "2"
*HW_XG_VOLTAGE_UNIT "kV"
*HW_XG_WATT_MAX "2"
*HW_XG_WATT_UNIT "kW"
*HW_XG_WAVE_LENGTH_ALPHA1 "1.540593"
*HW_XG_WAVE_LENGTH_ALPHA2 "1.544414"
*HW_XG_WAVE_LENGTH_BETA "1.392250"
*MEAS_COND_AXIS_NAME-0 "Theta/2-Theta"
*MEAS_COND_AXIS_NAME-1 "2-Theta"
*MEAS_COND_AXIS_NAME-2 "Omega"
*MEAS_COND_AXIS_NAME-3 "Chi"
*MEAS_COND_AXIS_NAME-4 "Phi"
*MEAS_COND_AXIS_NAME-5 "Z"
*MEAS_COND_AXIS_NAME-6 "X"
*MEAS_COND_AXIS_NAME-7 "Y"
*MEAS_COND_AXIS_NAME-8 "2-Theta/Omega"
*MEAS_COND_AXIS_NAME-9 "Theta_s"
*MEAS_COND_AXIS_NAME-10 "Theta_d"
*MEAS_COND_AXIS_NAME-11 "Ts"
*MEAS_COND_AXIS_NAME-12 "CBO selection slit"
*MEAS_COND_AXIS_NAME-13 "M"
*MEAS_COND_AXIS_NAME-14 "Incident parallel slit"
*MEAS_COND_AXIS_NAME-15 "Incident slit"
*MEAS_COND_AXIS_NAME-16 ""
*MEAS_COND_AXIS_NAME-17 "Zs"
*MEAS_COND_AXIS_NAME-18 "Incident monochromator"
*MEAS_COND_AXIS_NAME-19 "Length limiting slit"
*MEAS_COND_AXIS_NAME-20 "Center slit"
*MEAS_COND_AXIS_NAME-21 "Filter"
*MEAS_COND_AXIS_NAME-22 "Receiving slit # 1"
*MEAS_COND_AXIS_NAME-23 "Receiving slit # 2"
*MEAS_COND_AXIS_NAME-24 "Receiving optical device"
*MEAS_COND_AXIS_NAME-25 "Receiving parallel slit"
*MEAS_COND_AXIS_NAME-26 "Alignment receiving slit"
*MEAS_COND_AXIS_NAME-27 ""
*MEAS_COND_AXIS_NAME-28 ""
*MEAS_COND_AXIS_NAME-29 "Zd"
*MEAS_COND_AXIS_NAME-30 "Attenuator"
*MEAS_COND_AXIS_NAME-31 "Diffracted beam monochromator"
*MEAS_COND_AXIS_NAME-32 "Monochromator slit"
*MEAS_COND_AXIS_NAME-33 ""
*MEAS_COND_AXIS_NAME-34 ""
*MEAS_COND_AXIS_NAME-35 "Zr"
*MEAS_COND_AXIS_NAME-36 "Primary beam"
*MEAS_COND_AXIS_NAME_INTERNAL-0 "TwoThetaTheta"
*MEAS_COND_AXIS_NAME_INTERNAL-1 "TwoTheta"
*MEAS_COND_AXIS_NAME_INTERNAL-2 "Omega"
*MEAS_COND_AXIS_NAME_INTERNAL-3 "Chi"
*MEAS_COND_AXIS_NAME_INTERNAL-4 "Phi"
*MEAS_COND_AXIS_NAME_INTERNAL-5 "Z"
*MEAS_COND_AXIS_NAME_INTERNAL-6 "X"
*MEAS_COND_AXIS_NAME_INTERNAL-7 "Y"
*MEAS_COND_AXIS_NAME_INTERNAL-8 "TwoThetaOmega"
*MEAS_COND_AXIS_NAME_INTERNAL-9 "ThetaS"
*MEAS_COND_AXIS_NAME_INTERNAL-10 "ThetaD"
*MEAS_COND_AXIS_NAME_INTERNAL-11 "Ts"
*MEAS_COND_AXIS_NAME_INTERNAL-12 "CBO"
*MEAS_COND_AXIS_NAME_INTERNAL-13 "CBO-M"
*MEAS_COND_AXIS_NAME_INTERNAL-14 "IncidentSollerSlit"
*MEAS_COND_AXIS_NAME_INTERNAL-15 "IncidentSlitBox"
*MEAS_COND_AXIS_NAME_INTERNAL-16 "IncidentSlitBox-_Axis"
*MEAS_COND_AXIS_NAME_INTERNAL-17 "Zs"
*MEAS_COND_AXIS_NAME_INTERNAL-18 "IncidentMonochromator"
*MEAS_COND_AXIS_NAME_INTERNAL-19 "IncidentAxdSlit"
*MEAS_COND_AXIS_NAME_INTERNAL-20 "CenterSlit"
*MEAS_COND_AXIS_NAME_INTERNAL-21 "Filter"
*MEAS_COND_AXIS_NAME_INTERNAL-22 "ReceivingSlitBox1"
*MEAS_COND_AXIS_NAME_INTERNAL-23 "ReceivingSlitBox2"
*MEAS_COND_AXIS_NAME_INTERNAL-24 "ReceivingOptics"
*MEAS_COND_AXIS_NAME_INTERNAL-25 "ReceivingSollerSlit"
*MEAS_COND_AXIS_NAME_INTERNAL-26 "ReceivingAxdSlit"
*MEAS_COND_AXIS_NAME_INTERNAL-27 "ReceivingSlitBox1-_Axis"
*MEAS_COND_AXIS_NAME_INTERNAL-28 "ReceivingSlitBox2-_Axis"
*MEAS_COND_AXIS_NAME_INTERNAL-29 "ReceivingSlitBox2-Zd"
*MEAS_COND_AXIS_NAME_INTERNAL-30 "Attenuator"
*MEAS_COND_AXIS_NAME_INTERNAL-31 "CounterMonochromator"
*MEAS_COND_AXIS_NAME_INTERNAL-32 "CounterSlit"
*MEAS_COND_AXIS_NAME_INTERNAL-33 "AlphaR"
*MEAS_COND_AXIS_NAME_INTERNAL-34 "BetaR"
*MEAS_COND_AXIS_NAME_INTERNAL-35 "ReceivingSlitBox1-Zr"
*MEAS_COND_AXIS_NAME_INTERNAL-36 "IncidentPrimary"
*MEAS_COND_AXIS_NAME_MAGICNO-0 "83951616.0000000000"
*MEAS_COND_AXIS_NAME_MAGICNO-1 "268632064.0000000000"
*MEAS_COND_AXIS_NAME_MAGICNO-2 "268500992.0000000000"
*MEAS_COND_AXIS_NAME_MAGICNO-3 "268500992.0000000000"
*MEAS_COND_AXIS_NAME_MAGICNO-4 "268500992.0000000000"
*MEAS_COND_AXIS_NAME_MAGICNO-5 "285278208.0000000000"
*MEAS_COND_AXIS_NAME_MAGICNO-6 "268500992.0000000000"
*MEAS_COND_AXIS_NAME_MAGICNO-7 "268500992.0000000000"
*MEAS_COND_AXIS_NAME_MAGICNO-8 "83951616.0000000000"
*MEAS_COND_AXIS_NAME_MAGICNO-9 "131072.0000000000"
*MEAS_COND_AXIS_NAME_MAGICNO-10 "131072.0000000000"
*MEAS_COND_AXIS_NAME_MAGICNO-11 "318898176.0000000000"
*MEAS_COND_AXIS_NAME_MAGICNO-12 "20971521.0000000000"
*MEAS_COND_AXIS_NAME_MAGICNO-13 "285343744.0000000000"
*MEAS_COND_AXIS_NAME_MAGICNO-14 "20971521.0000000000"
*MEAS_COND_AXIS_NAME_MAGICNO-15 "22020097.0000000000"
*MEAS_COND_AXIS_NAME_MAGICNO-16 "25165824.0000000000"
*MEAS_COND_AXIS_NAME_MAGICNO-17 "318898176.0000000000"
*MEAS_COND_AXIS_NAME_MAGICNO-18 "1.0000000000"
*MEAS_COND_AXIS_NAME_MAGICNO-19 "20971521.0000000000"
*MEAS_COND_AXIS_NAME_MAGICNO-20 "20971521.0000000000"
*MEAS_COND_AXIS_NAME_MAGICNO-21 "20971521.0000000000"
*MEAS_COND_AXIS_NAME_MAGICNO-22 "23068673.0000000000"
*MEAS_COND_AXIS_NAME_MAGICNO-23 "23068673.0000000000"
*MEAS_COND_AXIS_NAME_MAGICNO-24 "20971521.0000000000"
*MEAS_COND_AXIS_NAME_MAGICNO-25 "20971521.0000000000"
*MEAS_COND_AXIS_NAME_MAGICNO-26 "20971521.0000000000"
*MEAS_COND_AXIS_NAME_MAGICNO-27 "25165824.0000000000"
*MEAS_COND_AXIS_NAME_MAGICNO-28 "25165824.0000000000"
*MEAS_COND_AXIS_NAME_MAGICNO-29 "285343744.0000000000"
*MEAS_COND_AXIS_NAME_MAGICNO-30 "0.0000000000"
*MEAS_COND_AXIS_NAME_MAGICNO-31 "20971521.0000000000"
*MEAS_COND_AXIS_NAME_MAGICNO-32 "20971521.0000000000"
*MEAS_COND_AXIS_NAME_MAGICNO-33 "8388608.0000000000"
*MEAS_COND_AXIS_NAME_MAGICNO-34 "8388608.0000000000"
*MEAS_COND_AXIS_NAME_MAGICNO-35 "285343744.0000000000"
*MEAS_COND_AXIS_NAME_MAGICNO-36 "20971521.0000000000"
*MEAS_COND_AXIS_OFFSET-0 "-"
*MEAS_COND_AXIS_OFFSET-1 "0.8371000000"
*MEAS_COND_AXIS_OFFSET-2 "0.7255000000"
*MEAS_COND_AXIS_OFFSET-3 "0.0000000000"
*MEAS_COND_AXIS_OFFSET-4 "0.0000000000"
*MEAS_COND_AXIS_OFFSET-5 "-"
*MEAS_COND_AXIS_OFFSET-6 "0.0000000000"
*MEAS_COND_AXIS_OFFSET-7 "0.0000000000"
*MEAS_COND_AXIS_OFFSET-8 "-"
*MEAS_COND_AXIS_OFFSET-9 "0.7255000000"
*MEAS_COND_AXIS_OFFSET-10 "0.1116000000"
*MEAS_COND_AXIS_OFFSET-11 "-"
*MEAS_COND_AXIS_OFFSET-12 "-"
*MEAS_COND_AXIS_OFFSET-13 "-"
*MEAS_COND_AXIS_OFFSET-14 "-"
*MEAS_COND_AXIS_OFFSET-15 "-"
*MEAS_COND_AXIS_OFFSET-16 "-"
*MEAS_COND_AXIS_OFFSET-17 "-"
*MEAS_COND_AXIS_OFFSET-18 "-"
*MEAS_COND_AXIS_OFFSET-19 "-"
*MEAS_COND_AXIS_OFFSET-20 "-"
*MEAS_COND_AXIS_OFFSET-21 "-"
*MEAS_COND_AXIS_OFFSET-22 "-"
*MEAS_COND_AXIS_OFFSET-23 "-"
*MEAS_COND_AXIS_OFFSET-24 "-"
*MEAS_COND_AXIS_OFFSET-25 "-"
*MEAS_COND_AXIS_OFFSET-26 "-"
*MEAS_COND_AXIS_OFFSET-27 "-"
*MEAS_COND_AXIS_OFFSET-28 "-"
*MEAS_COND_AXIS_OFFSET-29 "-"
*MEAS_COND_AXIS_OFFSET-30 "-"
*MEAS_COND_AXIS_OFFSET-31 "-"
*MEAS_COND_AXIS_OFFSET-32 "-"
*MEAS_COND_AXIS_OFFSET-33 "0.0000000000"
*MEAS_COND_AXIS_OFFSET-34 "0.0000000000"
*MEAS_COND_AXIS_OFFSET-35 "-"
*MEAS_COND_AXIS_OFFSET-36 "-"
*MEAS_COND_AXIS_POSITION-0 "0.0000000000"
*MEAS_COND_AXIS_POSITION-1 "0.0000000000"
*MEAS_COND_AXIS_POSITION-2 "0.0000000000"
*MEAS_COND_AXIS_POSITION-3 "0.0000000000"
*MEAS_COND_AXIS_POSITION-4 "0.0000000000"
*MEAS_COND_AXIS_POSITION-5 "-0.8364000000"
*MEAS_COND_AXIS_POSITION-6 "20.0000000000"
*MEAS_COND_AXIS_POSITION-7 "20.0000000000"
*MEAS_COND_AXIS_POSITION-8 "0.0000000000"
*MEAS_COND_AXIS_POSITION-9 "0.0000000000"
*MEAS_COND_AXIS_POSITION-10 "0.0000000000"
*MEAS_COND_AXIS_POSITION-11 "0.7586200000"
*MEAS_COND_AXIS_POSITION-12 "PB"
*MEAS_COND_AXIS_POSITION-13 "0.0000000000"
*MEAS_COND_AXIS_POSITION-14 "Soller_slit_5.0deg"
*MEAS_COND_AXIS_POSITION-15 "1.000mm"
*MEAS_COND_AXIS_POSITION-16 "1.0000000000"
*MEAS_COND_AXIS_POSITION-17 "-1.2518800000"
*MEAS_COND_AXIS_POSITION-18 "0.0000000000"
*MEAS_COND_AXIS_POSITION-19 "2.0mm"
*MEAS_COND_AXIS_POSITION-20 "None"
*MEAS_COND_AXIS_POSITION-21 "None"
*MEAS_COND_AXIS_POSITION-22 "2.000mm"
*MEAS_COND_AXIS_POSITION-23 "2.100mm"
*MEAS_COND_AXIS_POSITION-24 "PSA_open"
*MEAS_COND_AXIS_POSITION-25 "Soller_slit_5.0deg"
*MEAS_COND_AXIS_POSITION-26 "None"
*MEAS_COND_AXIS_POSITION-27 "2.0000000000"
*MEAS_COND_AXIS_POSITION-28 "2.1000000000"
*MEAS_COND_AXIS_POSITION-29 "0.0000000000"
*MEAS_COND_AXIS_POSITION-30 "-"
*MEAS_COND_AXIS_POSITION-31 "No_unit"
*MEAS_COND_AXIS_POSITION-32 "None"
*MEAS_COND_AXIS_POSITION-33 "0.0000000000"
*MEAS_COND_AXIS_POSITION-34 "0.0000000000"
*MEAS_COND_AXIS_POSITION-35 "-0.2509400000"
*MEAS_COND_AXIS_POSITION-36 "None"
*MEAS_COND_AXIS_UNIT-0 "deg"
*MEAS_COND_AXIS_UNIT-1 "deg"
*MEAS_COND_AXIS_UNIT-2 "deg"
*MEAS_COND_AXIS_UNIT-3 "deg"
*MEAS_COND_AXIS_UNIT-4 "deg"
*MEAS_COND_AXIS_UNIT-5 "mm"
*MEAS_COND_AXIS_UNIT-6 "mm"
*MEAS_COND_AXIS_UNIT-7 "mm"
*MEAS_COND_AXIS_UNIT-8 "deg"
*MEAS_COND_AXIS_UNIT-9 "deg"
*MEAS_COND_AXIS_UNIT-10 "deg"
*MEAS_COND_AXIS_UNIT-11 "mm"
*MEAS_COND_AXIS_UNIT-12 ""
*MEAS_COND_AXIS_UNIT-13 "pulse"
*MEAS_COND_AXIS_UNIT-14 ""
*MEAS_COND_AXIS_UNIT-15 ""
*MEAS_COND_AXIS_UNIT-16 "mm"
*MEAS_COND_AXIS_UNIT-17 "mm"
*MEAS_COND_AXIS_UNIT-18 ""
*MEAS_COND_AXIS_UNIT-19 ""
*MEAS_COND_AXIS_UNIT-20 ""
*MEAS_COND_AXIS_UNIT-21 ""
*MEAS_COND_AXIS_UNIT-22 ""
*MEAS_COND_AXIS_UNIT-23 ""
*MEAS_COND_AXIS_UNIT-24 ""
*MEAS_COND_AXIS_UNIT-25 ""
*MEAS_COND_AXIS_UNIT-26 ""
*MEAS_COND_AXIS_UNIT-27 "mm"
*MEAS_COND_AXIS_UNIT-28 "mm"
*MEAS_COND_AXIS_UNIT-29 "mm"
*MEAS_COND_AXIS_UNIT-30 ""
*MEAS_COND_AXIS_UNIT-31 ""
*MEAS_COND_AXIS_UNIT-32 ""
*MEAS_COND_AXIS_UNIT-33 "deg"
*MEAS_COND_AXIS_UNIT-34 "deg"
*MEAS_COND_AXIS_UNIT-35 "mm"
*MEAS_COND_AXIS_UNIT-36 ""
*MEAS_COND_COUNTER_CNTLOSS_CORR "0.0000000000"
*MEAS_COND_COUNTER_TAUDIFF "0.0000000000"
*MEAS_COND_COUNTER_TAUINT "0.0000000000"
*MEAS_COND_COUNTER_TEMP_CONDITION "NORMAL"
*MEAS_COND_IRRADIATION_MODE "OFF"
*MEAS_COND_IRRADIATION_WIDTH ""
*MEAS_COND_OPT_ATTR "Medium resolution parallel beam/RS"
*MEAS_COND_OPT_NAME "@Medium resolution PB"
*MEAS_COND_UNSYMMETRIC_MODE "OFF"
*MEAS_COND_XG_CURRENT "40.0000000000"
*MEAS_COND_XG_VOLTAGE "40.0000000000"
*MEAS_COND_XG_WAVE_TYPE "Ka"
*MEAS_DATA_COUNT "451.0000000000"
*MEAS_SCAN_AXIS_X "2-Theta/Omega"
*MEAS_SCAN_AXIS_X_INTERNAL "TwoThetaOmega"
*MEAS_SCAN_END_TIME "02/09/19 05:58:21"
*MEAS_SCAN_MODE "CONTINUOUS"
*MEAS_SCAN_MONITOR "0"
*MEAS_SCAN_RESOLUTION_X "0.0002"
*MEAS_SCAN_SPEED "3.005543"
*MEAS_SCAN_SPEED_UNIT "deg/min"
*MEAS_SCAN_SPEED_USER "3.000000"
*MEAS_SCAN_START "5.0000000000"
*MEAS_SCAN_START_TIME "02/09/19 05:43:08"
*MEAS_SCAN_STEP "0.1000000000"
*MEAS_SCAN_STOP "50.0000000000"
*MEAS_SCAN_UNIT_X "deg"
*MEAS_SCAN_UNIT_Y "counts"
*RAS_HEADER_END
*RAS_INT_START
5.0000 3075.9060 1.0000
5.1000 3086.1440 1.0000
5.2000 3236.8406 1.0000
5.3000 3639.2935 1.0000
5.4000 4266.8237 1.0000
5.5000 4605.7710 1.0000
5.6000 5343.7300 1.0000
5.7000 5864.1060 1.0000
5.8000 6612.8452 1.0000
5.9000 6679.1489 1.0000
6.0000 6745.3516 1.0000
6.1000 6311.5469 1.0000
6.2000 5853.3911 1.0000
6.3000 5143.9321 1.0000
6.4000 4635.9790 1.0000
6.5000 3782.8413 1.0000
6.6000 3068.2217 1.0000
6.7000 2570.1914 1.0000
6.8000 2041.0066 1.0000
6.9000 1735.4469 1.0000
7.0000 1382.5182 1.0000
7.1000 1134.6907 1.0000
7.2000 944.4466 1.0000
7.3000 806.0299 1.0000
7.4000 715.2441 1.0000
7.5000 647.6608 1.0000
7.6000 565.2917 1.0000
7.7000 521.4108 1.0000
7.8000 511.3691 1.0000
7.9000 447.0001 1.0000
8.0000 424.9465 1.0000
8.1000 425.4941 1.0000
8.2000 431.3691 1.0000
8.3000 411.4108 1.0000
8.4000 448.2858 1.0000
8.5000 494.4882 1.0000
8.6000 528.0536 1.0000
8.7000 513.1608 1.0000
8.8000 544.7322 1.0000
8.9000 513.9048 1.0000
9.0000 557.7858 1.0000
9.1000 567.9048 1.0000
9.2000 553.6608 1.0000
9.3000 508.9108 1.0000
9.4000 473.8156 1.0000
9.5000 436.3751 1.0000
9.6000 402.4941 1.0000
9.7000 362.2501 1.0000
9.8000 323.2084 1.0000
9.9000 296.2858 1.0000
10.0000 291.4465 1.0000
10.1000 281.2917 1.0000
10.2000 229.2857 1.0000
10.3000 202.3691 1.0000
10.4000 188.1607 1.0000
10.5000 203.1250 1.0000
10.6000 207.1607 1.0000
10.7000 174.1250 1.0000
10.8000 201.2857 1.0000
10.9000 213.2084 1.0000
11.0000 191.0000 1.0000
11.1000 173.1250 1.0000
11.2000 171.2084 1.0000
11.3000 184.8155 1.0000
11.4000 173.0000 1.0000
11.5000 169.1250 1.0000
11.6000 203.0000 1.0000
11.7000 211.3750 1.0000
11.8000 215.3334 1.0000
11.9000 207.0834 1.0000
12.0000 224.0834 1.0000
12.1000 211.0000 1.0000
12.2000 235.3750 1.0000
12.3000 248.1667 1.0000
12.4000 198.0000 1.0000
12.5000 204.0834 1.0000
12.6000 167.3334 1.0000
12.7000 159.2084 1.0000
12.8000 158.0000 1.0000
12.9000 144.1250 1.0000
13.0000 152.0000 1.0000
13.1000 175.0000 1.0000
13.2000 139.2857 1.0000
13.3000 154.0000 1.0000
13.4000 130.4107 1.0000
13.5000 156.0000 1.0000
13.6000 152.0000 1.0000
13.7000 166.4465 1.0000
13.8000 146.1250 1.0000
13.9000 155.2500 1.0000
14.0000 165.8572 1.0000
14.1000 153.0000 1.0000
14.2000 158.4107 1.0000
14.3000 163.3214 1.0000
14.4000 187.3334 1.0000
14.5000 182.4107 1.0000
14.6000 232.3334 1.0000
14.7000 239.4108 1.0000
14.8000 303.1250 1.0000
14.9000 366.2858 1.0000
15.0000 434.8632 1.0000
15.1000 497.4941 1.0000
15.2000 546.4941 1.0000
15.3000 541.1608 1.0000
15.4000 489.6548 1.0000
15.5000 406.9108 1.0000
15.6000 271.0834 1.0000
15.7000 227.4465 1.0000
15.8000 191.1250 1.0000
15.9000 190.0000 1.0000
16.0000 153.5357 1.0000
16.1000 110.0000 1.0000
16.2000 117.5357 1.0000
16.3000 104.0000 1.0000
16.4000 120.1667 1.0000
16.5000 122.0000 1.0000
16.6000 97.0000 1.0000
16.7000 112.0000 1.0000
16.8000 87.1607 1.0000
16.9000 102.0000 1.0000
17.0000 79.0000 1.0000
17.1000 84.0833 1.0000
17.2000 81.0000 1.0000
17.3000 93.1250 1.0000
17.4000 106.1250 1.0000
17.5000 114.2857 1.0000
17.6000 118.0000 1.0000
17.7000 122.0834 1.0000
17.8000 138.0000 1.0000
17.9000 143.0000 1.0000
18.0000 153.0000 1.0000
18.1000 191.3334 1.0000
18.2000 216.0834 1.0000
18.3000 209.1250 1.0000
18.4000 242.1250 1.0000
18.5000 234.2084 1.0000
18.6000 207.4107 1.0000
18.7000 194.4107 1.0000
18.8000 151.4941 1.0000
18.9000 152.4107 1.0000
19.0000 106.0000 1.0000
19.1000 100.4464 1.0000
19.2000 103.1250 1.0000
19.3000 88.0000 1.0000
19.4000 98.0000 1.0000
19.5000 105.0000 1.0000
19.6000 103.0000 1.0000
19.7000 79.2500 1.0000
19.8000 86.0000 1.0000
19.9000 90.0000 1.0000
20.0000 83.0000 1.0000
20.1000 96.1250 1.0000
20.2000 87.0000 1.0000
20.3000 67.4107 1.0000
20.4000 82.1607 1.0000
20.5000 86.1250 1.0000
20.6000 101.0000 1.0000
20.7000 88.3691 1.0000
20.8000 105.2857 1.0000
20.9000 116.1250 1.0000
21.0000 90.0000 1.0000
21.1000 99.0000 1.0000
21.2000 127.2857 1.0000
21.3000 93.1250 1.0000
21.4000 120.1250 1.0000
21.5000 120.1250 1.0000
21.6000 129.2083 1.0000
21.7000 148.0834 1.0000
21.8000 120.0000 1.0000
21.9000 101.2857 1.0000
22.0000 87.2857 1.0000
22.1000 94.0000 1.0000
22.2000 99.1250 1.0000
22.3000 101.0833 1.0000
22.4000 82.1250 1.0000
22.5000 75.0000 1.0000
22.6000 96.1250 1.0000
22.7000 90.2857 1.0000
22.8000 88.0833 1.0000
22.9000 72.0833 1.0000
23.0000 76.2083 1.0000
23.1000 77.0000 1.0000
23.2000 75.0000 1.0000
23.3000 85.1250 1.0000
23.4000 85.2917 1.0000
23.5000 91.2857 1.0000
23.6000 87.0000 1.0000
23.7000 97.4941 1.0000
23.8000 89.1250 1.0000
23.9000 78.0000 1.0000
24.0000 95.0833 1.0000
24.1000 88.0833 1.0000
24.2000 99.0833 1.0000
24.3000 103.1250 1.0000
24.4000 110.3333 1.0000
24.5000 130.3333 1.0000
24.6000 91.0000 1.0000
24.7000 118.0000 1.0000
24.8000 106.4524 1.0000
24.9000 101.0000 1.0000
25.0000 97.4167 1.0000
25.1000 91.3691 1.0000
25.2000 92.1250 1.0000
25.3000 75.2857 1.0000
25.4000 87.2857 1.0000
25.5000 84.1250 1.0000
25.6000 83.0000 1.0000
25.7000 70.0000 1.0000
25.8000 68.0000 1.0000
25.9000 78.0000 1.0000
26.0000 56.5714 1.0000
26.1000 67.0000 1.0000
26.2000 81.1250 1.0000
26.3000 58.0000 1.0000
26.4000 84.0000 1.0000
26.5000 69.0000 1.0000
26.6000 73.1250 1.0000
26.7000 62.0000 1.0000
26.8000 68.0000 1.0000
26.9000 69.0000 1.0000
27.0000 88.0833 1.0000
27.1000 69.0833 1.0000
27.2000 80.0000 1.0000
27.3000 84.0833 1.0000
27.4000 105.0000 1.0000
27.5000 110.2857 1.0000
27.6000 135.2500 1.0000
27.7000 106.0000 1.0000
27.8000 124.0000 1.0000
27.9000 136.1250 1.0000
28.0000 143.1667 1.0000
28.1000 104.0000 1.0000
28.2000 118.0000 1.0000
28.3000 94.0000 1.0000
28.4000 102.2857 1.0000
28.5000 88.5774 1.0000
28.6000 95.0833 1.0000
28.7000 67.0000 1.0000
28.8000 103.0833 1.0000
28.9000 82.0000 1.0000
29.0000 94.2857 1.0000
29.1000 90.1607 1.0000
29.2000 106.0000 1.0000
29.3000 109.2441 1.0000
29.4000 117.2857 1.0000
29.5000 130.0833 1.0000
29.6000 107.0000 1.0000
29.7000 126.1607 1.0000
29.8000 166.2857 1.0000
29.9000 142.0000 1.0000
30.0000 170.2500 1.0000
30.1000 179.0834 1.0000
30.2000 249.2858 1.0000
30.3000 239.2500 1.0000
30.4000 321.0000 1.0000
30.5000 373.0001 1.0000
30.6000 422.4941 1.0000
30.7000 574.0656 1.0000
30.8000 629.7025 1.0000
30.9000 702.6548 1.0000
31.0000 639.5775 1.0000
31.1000 567.7798 1.0000
31.2000 476.4108 1.0000
31.3000 467.8215 1.0000
31.4000 365.8215 1.0000
31.5000 319.6965 1.0000
31.6000 269.0834 1.0000
31.7000 213.9822 1.0000
31.8000 204.0000 1.0000
31.9000 165.1250 1.0000
32.0000 187.6607 1.0000
32.1000 135.0000 1.0000
32.2000 151.0000 1.0000
32.3000 147.1250 1.0000
32.4000 138.0000 1.0000
32.5000 138.0000 1.0000
32.6000 140.1250 1.0000
32.7000 116.0834 1.0000
32.8000 130.0000 1.0000
32.9000 107.0000 1.0000
33.0000 113.0000 1.0000
33.1000 116.0000 1.0000
33.2000 110.0000 1.0000
33.3000 140.2441 1.0000
33.4000 142.2857 1.0000
33.5000 128.0833 1.0000
33.6000 178.2500 1.0000
33.7000 190.0000 1.0000
33.8000 216.2857 1.0000
33.9000 212.6607 1.0000
34.0000 197.0000 1.0000
34.1000 196.0000 1.0000
34.2000 198.0000 1.0000
34.3000 195.3334 1.0000
34.4000 147.1607 1.0000
34.5000 121.0000 1.0000
34.6000 100.2857 1.0000
34.7000 90.2083 1.0000
34.8000 83.0000 1.0000
34.9000 75.0000 1.0000
35.0000 62.2083 1.0000
35.1000 59.1250 1.0000
35.2000 59.0000 1.0000
35.3000 53.0000 1.0000
35.4000 41.2083 1.0000
35.5000 47.0000 1.0000
35.6000 53.1607 1.0000
35.7000 52.0000 1.0000
35.8000 47.0000 1.0000
35.9000 45.0000 1.0000
36.0000 40.0833 1.0000
36.1000 41.0000 1.0000
36.2000 45.0000 1.0000
36.3000 39.0000 1.0000
36.4000 38.0000 1.0000
36.5000 43.0000 1.0000
36.6000 44.0000 1.0000
36.7000 38.0000 1.0000
36.8000 44.0000 1.0000
36.9000 42.0000 1.0000
37.0000 54.0000 1.0000
37.1000 44.0000 1.0000
37.2000 49.0000 1.0000
37.3000 38.0000 1.0000
37.4000 32.0000 1.0000
37.5000 59.3691 1.0000
37.6000 51.0000 1.0000
37.7000 46.2441 1.0000
37.8000 36.1250 1.0000
37.9000 32.0000 1.0000
38.0000 40.0000 1.0000
38.1000 35.0000 1.0000
38.2000 40.2857 1.0000
38.3000 45.1250 1.0000
38.4000 35.1250 1.0000
38.5000 40.0000 1.0000
38.6000 32.0000 1.0000
38.7000 36.0000 1.0000
38.8000 37.0833 1.0000
38.9000 31.0000 1.0000
39.0000 34.0000 1.0000
39.1000 37.0000 1.0000
39.2000 33.1607 1.0000
39.3000 51.0000 1.0000
39.4000 47.0833 1.0000
39.5000 35.0000 1.0000
39.6000 32.0000 1.0000
39.7000 47.0000 1.0000
39.8000 33.0000 1.0000
39.9000 35.0000 1.0000
40.0000 31.0000 1.0000
40.1000 48.1250 1.0000
40.2000 35.0000 1.0000
40.3000 36.0000 1.0000
40.4000 33.0833 1.0000
40.5000 34.0000 1.0000
40.6000 49.0000 1.0000
40.7000 50.0000 1.0000
40.8000 38.0000 1.0000
40.9000 30.2857 1.0000
41.0000 46.1607 1.0000
41.1000 35.2857 1.0000
41.2000 34.0000 1.0000
41.3000 29.0000 1.0000
41.4000 31.0000 1.0000
41.5000 28.0000 1.0000
41.6000 28.0000 1.0000
41.7000 36.1250 1.0000
41.8000 31.0000 1.0000
41.9000 36.0000 1.0000
42.0000 27.0000 1.0000
42.1000 27.0000 1.0000
42.2000 40.0000 1.0000
42.3000 45.2857 1.0000
42.4000 36.0833 1.0000
42.5000 36.0000 1.0000
42.6000 35.0833 1.0000
42.7000 36.0000 1.0000
42.8000 26.0000 1.0000
42.9000 28.0000 1.0000
43.0000 38.0000 1.0000
43.1000 38.0000 1.0000
43.2000 27.0000 1.0000
43.3000 33.0000 1.0000
43.4000 31.0000 1.0000
43.5000 33.0000 1.0000
43.6000 34.0000 1.0000
43.7000 32.0000 1.0000
43.8000 29.0000 1.0000
43.9000 30.0000 1.0000
44.0000 45.3691 1.0000
44.1000 36.0000 1.0000
44.2000 35.0000 1.0000
44.3000 36.0000 1.0000
44.4000 29.0000 1.0000
44.5000 38.2857 1.0000
44.6000 32.0833 1.0000
44.7000 24.0000 1.0000
44.8000 39.2857 1.0000
44.9000 33.0000 1.0000
45.0000 31.0000 1.0000
45.1000 22.0000 1.0000
45.2000 32.0000 1.0000
45.3000 31.0833 1.0000
45.4000 39.0000 1.0000
45.5000 26.0000 1.0000
45.6000 26.0000 1.0000
45.7000 25.0000 1.0000
45.8000 32.0000 1.0000
45.9000 28.0000 1.0000
46.0000 40.0000 1.0000
46.1000 36.0000 1.0000
46.2000 39.0000 1.0000
46.3000 27.0000 1.0000
46.4000 36.0000 1.0000
46.5000 39.0000 1.0000
46.6000 36.0000 1.0000
46.7000 20.0000 1.0000
46.8000 34.0000 1.0000
46.9000 29.0000 1.0000
47.0000 30.0000 1.0000
47.1000 35.0000 1.0000
47.2000 29.0000 1.0000
47.3000 27.0000 1.0000
47.4000 21.0000 1.0000
47.5000 30.0000 1.0000
47.6000 28.0833 1.0000
47.7000 36.1250 1.0000
47.8000 34.2857 1.0000
47.9000 30.0000 1.0000
48.0000 46.0000 1.0000
48.1000 29.1250 1.0000
48.2000 26.0000 1.0000
48.3000 29.2857 1.0000
48.4000 27.0000 1.0000
48.5000 33.2083 1.0000
48.6000 34.0000 1.0000
48.7000 24.0000 1.0000
48.8000 31.0000 1.0000
48.9000 31.0000 1.0000
49.0000 31.2857 1.0000
49.1000 25.0000 1.0000
49.2000 32.0000 1.0000
49.3000 31.0000 1.0000
49.4000 32.0000 1.0000
49.5000 26.0000 1.0000
49.6000 34.0000 1.0000
49.7000 29.0000 1.0000
49.8000 30.0000 1.0000
49.9000 22.0000 1.0000
50.0000 24.0000 1.0000
*RAS_INT_END
*RAS_DATA_END